<?xml version="1.0" encoding="UTF-8"?>
<!-- Generated by org.testng.reporters.JUnitXMLReporter -->
<testsuite hostname="MSI" name="Default test" tests="4" failures="1" timestamp="6 Oct 2018 01:59:59 GMT" time="38.932" errors="0">
  <testcase name="feature" time="9.785" classname="cucumberclasses.NGCucumberRunner"/>
  <testcase name="feature" time="10.69" classname="cucumberclasses.NGCucumberRunner">
    <failure type="cucumber.runtime.CucumberException" message="java.lang.AssertionError: expected [40] but found [0]">
      <![CDATA[cucumber.runtime.CucumberException: java.lang.AssertionError: expected [40] but found [0]
	at cucumber.api.testng.TestNGCucumberRunner.runCucumber(TestNGCucumberRunner.java:69)
	at cucumber.api.testng.AbstractTestNGCucumberTests.feature(AbstractTestNGCucumberTests.java:21)
	at sun.reflect.NativeMethodAccessorImpl.invoke0(Native Method)
	at sun.reflect.NativeMethodAccessorImpl.invoke(Unknown Source)
	at sun.reflect.DelegatingMethodAccessorImpl.invoke(Unknown Source)
	at java.lang.reflect.Method.invoke(Unknown Source)
	at org.testng.internal.MethodInvocationHelper.invokeMethod(MethodInvocationHelper.java:86)
	at org.testng.internal.Invoker.invokeMethod(Invoker.java:643)
	at org.testng.internal.Invoker.invokeTestMethod(Invoker.java:820)
	at org.testng.internal.Invoker.invokeTestMethods(Invoker.java:1128)
	at org.testng.internal.TestMethodWorker.invokeTestMethods(TestMethodWorker.java:129)
	at org.testng.internal.TestMethodWorker.run(TestMethodWorker.java:112)
	at org.testng.TestRunner.privateRun(TestRunner.java:782)
	at org.testng.TestRunner.run(TestRunner.java:632)
	at org.testng.SuiteRunner.runTest(SuiteRunner.java:366)
	at org.testng.SuiteRunner.runSequentially(SuiteRunner.java:361)
	at org.testng.SuiteRunner.privateRun(SuiteRunner.java:319)
	at org.testng.SuiteRunner.run(SuiteRunner.java:268)
	at org.testng.SuiteRunnerWorker.runSuite(SuiteRunnerWorker.java:52)
	at org.testng.SuiteRunnerWorker.run(SuiteRunnerWorker.java:86)
	at org.testng.TestNG.runSuitesSequentially(TestNG.java:1244)
	at org.testng.TestNG.runSuitesLocally(TestNG.java:1169)
	at org.testng.TestNG.run(TestNG.java:1064)
	at org.testng.remote.AbstractRemoteTestNG.run(AbstractRemoteTestNG.java:114)
	at org.testng.remote.RemoteTestNG.initAndRun(RemoteTestNG.java:251)
	at org.testng.remote.RemoteTestNG.main(RemoteTestNG.java:77)
Caused by: java.lang.AssertionError: expected [40] but found [0]
	at org.testng.Assert.fail(Assert.java:94)
	at org.testng.Assert.failNotEquals(Assert.java:513)
	at org.testng.Assert.assertEqualsImpl(Assert.java:135)
	at org.testng.Assert.assertEquals(Assert.java:116)
	at org.testng.Assert.assertEquals(Assert.java:389)
	at org.testng.Assert.assertEquals(Assert.java:399)
	at cucumberclasses.TrainerPageCucumber.a_new_Trainer_should_appear_on_the_list_of_Trainers_with_the_proper_fields_I_filled_in(TrainerPageCucumber.java:164)
	at âœ½.Then a new Trainer should appear on the list of Trainers with the proper fields I filled in.(src/test/resources/AddTrainerValidInput.feature:9)
]]>
    </failure>
  </testcase> <!-- feature -->
  <testcase name="feature" time="9.402" classname="cucumberclasses.NGCucumberRunner"/>
  <testcase name="feature" time="8.785" classname="cucumberclasses.NGCucumberRunner"/>
</testsuite> <!-- Default test -->
